Workbook

Sheet 00_Guia_de_Uso
A1: Guía de uso · Automatización reporte Maicao
A2: Versión v04: validaciones automáticas + fallback visual + KPIs por plataforma desde Excel
A4: Paso | B4: Qué hacer | C4: Dónde editar | D4: Cuándo hacerlo
A5: 1 | B5: Definir cliente, mes actual y mes anterior. Usa texto exacto tipo Marzo 2026, no fecha. | C5: 00_Control | D5: Siempre al iniciar un reporte
A6: 2 | B6: Actualizar KPIs oficiales por plataforma: views, alcance, interacciones, ER, contenidos, formatos, presupuesto y Top 3. | C6: 13_Platform_KPIs | D6: Siempre. Alimenta Instagram, Facebook, TikTok y portafolio de canales.
A7: 3 | B7: Actualizar seguidores y demografía por plataforma. | C7: 02_Audience | D7: Siempre que cambie la audiencia.
A8: 4 | B8: Actualizar inversión por plataforma/segmento. | C8: 03_Paid_Media | D8: Cuando cambie pauta o presupuesto.
A9: 5 | B9: Actualizar Squad y MMPP si aplica al mes. | C9: 04_Squad / 05_MMPP | D9: Cuando existan secciones en el reporte.
A10: 6 | B10: Completar insights y recomendaciones cualitativas. | C10: 07_Insights / 08_Recomendaciones | D10: Antes de generar la versión cliente.
A11: 7 | B11: Revisar checklist. Si algo dice REVISAR, corregir antes de generar. | C11: 15_Checklist_Generacion | D11: Antes de ejecutar el generador.
A12: 8 | B12: Generar PPT con doble clic o Terminal. | C12: GENERAR_REPORTE.command / python3 generate_report_from_template.py | D12: Al finalizar la carga.
A14: Notas v04 | B14: Si falta data, la PPT mostrará "Dato pendiente" y Terminal imprimirá una alerta concreta por hoja/plataforma/mes. El reporte de alertas queda en output/validation_report_v04.txt.

Sheet 00_Dashboard
A1: Maicao · Modelo de Automatización de Reporte
A2: Archivo maestro para cargar data, validar métricas y alimentar una PPT editable.
A4: Estado del modelo | D4: KPIs auditados desde hoja Marzo 2026
A6: Campo | B6: Valor | C6: Notas | E6: KPI | F6: Calculado desde Excel | G6: Valor esperado reporte | H6: Estado | J6: Módulo | K6: Qué resuelve | L6: Automatización
A7: Cliente | B7: Maicao | C7: Fuente: Excel agencia + reporte marzo | E7: Views | F7: 16485909 | G7: 16486179 | H7: =IF(F7=G7,"OK","Revisar") | J7: Data raw | K7: Una fila por contenido | L7: KPIs / top contenidos
A8: Mes actual | B8: Marzo 2026 | C8: Control del ciclo mensual | E8: Alcance | F8: 8211420 | G8: 8211420 | H8: =IF(F8=G8,"OK","Revisar") | J8: Insights | K8: Narrativa cualitativa estructurada | L8: Textos PPT
A9: Versión modelo | B9: v0.1 | C9: Estructura inicial | E9: Interacciones | F9: 110695 | G9: 110695 | H9: =IF(F9=G9,"OK","Revisar") | J9: Validaciones | K9: Alertas de descuadre | L9: QA mensual
A10: Estado | B10: Base creada | C10: Pendiente: mapping final PPT | E10: Contenidos | F10: 158 | G10: 156 | H10: =IF(F10=G10,"OK","Revisar criterio") | J10: Mapping PPT | K10: Conecta Excel con slides | L10: Generación pptx
A11: Próximo paso | B11: Migración + reglas | C11: Validar criterios de inclusión | E11: Inversión | F11: 2200000 | G11: 3800400 | H11: =IF(F11=G11,"OK","Revisar pauta")
A13: Mejora v03
A14: Se agregaron guía de uso, mapa slide por slide y KPIs oficiales por plataforma editables desde Excel.
A20: v04 mejora | B20: Validación automática, fallback visual, ajuste de tarjetas KPI y normalización de mes.

Sheet 00_Control
A1: 00_Control
A2: Parámetros del reporte mensual. La automatización lee esta hoja primero.
A4: Campo | B4: Valor | C4: Tipo | D4: Descripción
A5: Cliente | B5: Maicao | C5: Texto | D5: Nombre del cliente
A6: Mes actual | B6: Marzo 2026 | C6: Texto | D6: Mes a generar
A7: Mes anterior | B7: Febrero 2026 | C7: Texto | D7: Mes de comparación
A8: Moneda | B8: CLP | C8: Texto | D8: Formato monetario
A9: Responsable | B9: Agencia | C9: Texto | D9: Equipo que carga la data
A10: Versión | B10: v0.1 | C10: Texto | D10: Versión del modelo
A11: Estado | B11: Modelo v03 listo para prueba | C11: Lista | D11: En carga / Validado / Listo para PPT
A12: Ruta plantilla PPT | C12: Ruta | D12: Se completará en etapa 2
A13: Ruta output PPT | C13: Ruta | D13: Se completará en etapa 2

Sheet 01_Content_Raw
A1: 01_Content_Raw
A2: Base principal: una fila por contenido publicado. Incluye flags para controlar qué suma en cada sección.
A4: Mes | B4: Fecha | C4: Plataforma | D4: Categoría | E4: Formato | F4: Talento | G4: Tema | H4: Campaña | I4: Pilar de contenido | J4: Objetivo | K4: Views | L4: Alcance | M4: Me gusta | N4: Comentarios | O4: Enviados | P4: Reposteados | Q4: Guardados | R4: Clicks sticker | S4: Clicks link | T4: Interacciones totales | U4: ER % | V4: Patrocinio | W4: Monto | X4: Días | Y4: Incluir Overview | Z4: Incluir Plataforma | AA4: Incluir Squad | AB4: Incluir MMPP | AC4: Notas | AD4: URL / Evidencia
A5: Marzo 2026 | C5: Instagram | D5: EXTRA | E5: STORY | F5: maicao | G5: dcto banco estado | K5: 4842 | L5: 3989 | M5: 19 | N5: 1 | O5: 2 | P5: 0 | Q5: 0 | R5: 0 | S5: 98 | T5: 120 | U5: 3.0082728 | W5: 0 | Y5: Sí | Z5: Sí | AA5: No | AB5: No
A6: Marzo 2026 | C6: Instagram | D6: CONCURSO | E6: STORY | F6: maicao | G6: ganador essence catrice | K6: 6556 | L6: 5440 | M6: 53 | N6: 9 | O6: 10 | P6: 0 | Q6: 0 | R6: 73 | S6: 0 | T6: 145 | U6: 2.6654412 | W6: 0 | Y6: Sí | Z6: Sí | AA6: No | AB6: No
A7: Marzo 2026 | C7: Instagram | D7: CAMPAÑA | E7: STORY | F7: maicao | G7: Bienvenida squad y consejeras | K7: 3047 | L7: 2580 | M7: 54 | N7: 1 | O7: 6 | P7: 0 | Q7: 0 | R7: 0 | S7: 0 | T7: 61 | U7: 2.3643411 | W7: 0 | Y7: Sí | Z7: Sí | AA7: No | AB7: No
A8: Marzo 2026 | C8: Instagram | D8: EXTRA | E8: STORY | F8: maicao | G8: Repost la busquilla "bienvenida squad" | K8: 2541 | L8: 2207 | M8: 24 | N8: 1 | O8: 0 | P8: 0 | Q8: 0 | R8: 16 | S8: 0 | T8: 41 | U8: 1.8577254 | W8: 0 | Y8: Sí | Z8: Sí | AA8: No | AB8: No
A9: Marzo 2026 | C9: Instagram | D9: EXTRA | E9: STORY | F9: maicao | G9: repost skar "bienvenida squad" | K9: 2450 | L9: 2090 | M9: 46 | N9: 2 | O9: 0 | P9: 0 | Q9: 0 | R9: 10 | S9: 0 | T9: 58 | U9: 2.7751196 | W9: 0 | Y9: Sí | Z9: Sí | AA9: No | AB9: No
A10: Marzo 2026 | C10: Instagram | D10: EXTRA | E10: STORY | F10: maicao | G10: repost disley "bienvenida squad" | K10: 2445 | L10: 1998 | M10: 34 | N10: 0 | O10: 1 | P10: 0 | Q10: 0 | R10: 16 | S10: 0 | T10: 51 | U10: 2.5525526 | W10: 0 | Y10: Sí | Z10: Sí | AA10: No | AB10: No
A11: Marzo 2026 | C11: Instagram | D11: EXTRA | E11: STORY | F11: maicao | G11: repost conibulnesc "bienvenida squad" | K11: 2293 | L11: 1946 | M11: 19 | N11: 1 | O11: 0 | P11: 0 | Q11: 0 | R11: 17 | S11: 0 | T11: 37 | U11: 1.9013361 | W11: 0 | Y11: Sí | Z11: Sí | AA11: No | AB11: No
A12: Marzo 2026 | C12: Instagram | D12: CAMPAÑA | E12: STORY | F12: maicao | G12: Bienvenida squad y consejeras | K12: 2465 | L12: 2060 | M12: 22 | N12: 3 | O12: 4 | P12: 0 | Q12: 0 | R12: 8 | S12: 0 | T12: 37 | U12: 1.7961165 | W12: 0 | Y12: Sí | Z12: Sí | AA12: No | AB12: No
A13: Marzo 2026 | C13: Instagram | D13: EXTRA | E13: STORY | F13: maicao | G13: Repost la busquilla "bienvenida squad" | K13: 2989 | L13: 2319 | M13: 27 | N13: 0 | O13: 3 | P13: 0 | Q13: 0 | R13: 4 | S13: 0 | T13: 34 | U13: 1.4661492 | W13: 0 | Y13: Sí | Z13: Sí | AA13: No | AB13: No
A14: Marzo 2026 | C14: Instagram | D14: EXTRA | E14: STORY | F14: maicao | G14: repost skar dove en viña | K14: 1892 | L14: 1666 | M14: 31 | N14: 0 | O14: 2 | P14: 0 | Q14: 0 | R14: 2 | S14: 0 | T14: 35 | U14: 2.1008403 | W14: 0 | Y14: Sí | Z14: Sí | AA14: No | AB14: No
A15: Marzo 2026 | C15: Instagram | D15: EXTRA | E15: STORY | F15: maicao | G15: repost iribarne.din | K15: 2127 | L15: 1988 | M15: 19 | N15: 1 | O15: 0 | P15: 0 | Q15: 0 | R15: 10 | S15: 0 | T15: 30 | U15: 1.5090543 | W15: 0 | Y15: Sí | Z15: Sí | AA15: No | AB15: No
A16: Marzo 2026 | C16: Instagram | D16: EXTRA | E16: STORY | F16: maicao | G16: repost iribarne.din | K16: 1990 | L16: 1847 | M16: 20 | N16: 2 | O16: 1 | P16: 0 | Q16: 0 | R16: 2 | S16: 0 | T16: 25 | U16: 1.3535463 | W16: 0 | Y16: Sí | Z16: Sí | AA16: No | AB16: No
... A77: Marzo 2026 | C77: Instagram | D77: CAMPAÑA COLOR CRUSH | E77: REEL | F77: maicao | G77: sofia mezzano color crush | K77: 41826 | L77: 22880 | M77: 942 | N77: 174 | O77: 4 | P77: 23 | Q77: 40 | R77: 0 | S77: 0 | T77: 1183 | U77: 5.1704545 | W77: 0 | Y77: Sí | Z77: Sí | AA77: No | AB77: No
A78: Marzo 2026 | C78: Instagram | D78: RUTA | E78: REEL | F78: maicao | G78: ruta a qué hora se levantan | J78: Alcance | K78: 533805 | L78: 359691 | M78: 400 | N78: 17 | O78: 66 | P78: 17 | Q78: 10 | R78: 0 | S78: 0 | T78: 510 | U78: 0.14178837 | V78: Sí | W78: 200000 | X78: 7 | Y78: Sí | Z78: Sí | AA78: No | AB78: No
A79: Marzo 2026 | C79: Instagram | D79: UGC | E79: REEL | F79: maicao | G79: repost makeup inspo para la u | J79: Alcance | K79: 1042328 | L79: 543425 | M79: 980 | N79: 3 | O79: 28 | P79: 12 | Q79: 71 | R79: 0 | S79: 0 | T79: 1094 | U79: 0.20131573 | V79: Sí | W79: 200000 | X79: 7 | Y79: Sí | Z79: Sí | AA79: No | AB79: No
A80: Marzo 2026 | C80: Instagram | D80: SAMY | E80: REEL | F80: maicao | G80: noeaylen mi día en la u | J80: Alcance | K80: 9911 | L80: 6569 | M80: 178 | N80: 26 | O80: 5 | P80: 6 | Q80: 23 | R80: 0 | S80: 0 | T80: 238 | U80: 3.6230781 | V80: Sí | W80: 200000 | X80: 5 | Y80: Sí | Z80: Sí | AA80: No | AB80: No
A81: Marzo 2026 | C81: Instagram | D81: UGC | E81: REEL | F81: maicao | G81: repost maquillaje para principiantes | J81: Alcance | K81: 507532 | L81: 364623 | M81: 359 | N81: 6 | O81: 21 | P81: 16 | Q81: 68 | R81: 0 | S81: 0 | T81: 470 | U81: 0.12890026 | V81: Sí | W81: 200000 | X81: 5 | Y81: Sí | Z81: Sí | AA81: No | AB81: No
A82: Marzo 2026 | C82: Instagram | D82: CONCURSO | E82: CARRUSEL | F82: maicao | G82: concurso maquillaje | K82: 24259 | L82: 9742 | M82: 980 | N82: 3500 | O82: 248 | P82: 368 | Q82: 126 | R82: 0 | S82: 0 | T82: 5222 | U82: 53.602956 | W82: 0 | Y82: Sí | Z82: Sí | AA82: No | AB82: No
A83: Marzo 2026 | C83: Instagram | D83: CAMPAÑA COLOR CRUSH | E83: REEL | F83: maicao | G83: muyjosefa | K83: 56332 | L83: 33757 | M83: 1112 | N83: 15 | O83: 34 | P83: 7 | Q83: 127 | R83: 0 | S83: 0 | T83: 1295 | U83: 3.8362414 | W83: 0 | Y83: Sí | Z83: Sí | AA83: No | AB83: No
A84: Marzo 2026 | C84: Instagram | D84: EXTRA | E84: CARRUSEL | F84: maicao | G84: día de la felicidad | K84: 7093 | L84: 2811 | M84: 66 | N84: 0 | O84: 18 | P84: 4 | Q84: 9 | R84: 0 | S84: 0 | T84: 97 | U84: 3.4507293 | W84: 0 | Y84: Sí | Z84: Sí | AA84: No | AB84: No
A85: Marzo 2026 | C85: Instagram | D85: SAMY | E85: REEL | F85: maicao | G85: que hay en mi cosmetiquero varasmusica | K85: 5215 | L85: 3702 | M85: 124 | N85: 28 | O85: 7 | P85: 11 | Q85: 13 | R85: 0 | S85: 0 | T85: 183 | U85: 4.9432739 | W85: 0 | Y85: Sí | Z85: Sí | AA85: No | AB85: No
A86: Marzo 2026 | C86: Instagram | D86: UGC | E86: CARRUSEL | F86: maicao | G86: por qué compras en maicao? | K86: 6314 | L86: 4785 | M86: 126 | N86: 14 | O86: 34 | P86: 13 | Q86: 3 | R86: 0 | S86: 0 | T86: 190 | U86: 3.9707419 | W86: 0 | Y86: Sí | Z86: Sí | AA86: No | AB86: No
A87: Marzo 2026 | C87: Instagram | D87: SABRINA CARPENTER | E87: REEL | F87: maicao | G87: teaser lemon pie isiortrippp | K87: 56780 | L87: 22514 | M87: 1702 | N87: 54 | O87: 18 | P87: 3 | Q87: 19 | R87: 0 | S87: 0 | T87: 1796 | U87: 7.9772586 | W87: 0 | Y87: Sí | Z87: Sí | AA87: No | AB87: No
A88: Marzo 2026 | C88: Instagram | D88: UGC | E88: CARRUSEL | F88: maicao | G88: repost hannah montana | K88: 15913 | L88: 7076 | M88: 406 | N88: 9 | O88: 20 | P88: 12 | Q88: 20 | R88: 0 | S88: 0 | T88: 467 | U88: 6.5997739 | W88: 0 | Y88: Sí | Z88: Sí | AA88: No | AB88: No
A89: Marzo 2026 | C89: Instagram | D89: SAMY | E89: REEL | F89: maicao | G89: glowup samy - velybeauty | K89: 4673 | L89: 3589 | M89: 64 | N89: 7 | O89: 2 | P89: 5 | Q89: 4 | R89: 0 | S89: 0 | T89: 82 | U89: 2.284759 | W89: 0 | Y89: Sí | Z89: Sí | AA89: No | AB89: Sí
A90: Marzo 2026 | C90: Instagram | D90: SABRINA CARPENTER | E90: CARRUSEL | F90: maicao | G90: teaser lemon pie - _carlabenavides | K90: 58302 | L90: 15960 | M90: 587 | N90: 18 | O90: 27 | P90: 5 | Q90: 7 | R90: 0 | S90: 0 | T90: 644 | U90: 4.0350877 | W90: 0 | Y90: Sí | Z90: Sí | AA90: No | AB90: No
A91: Marzo 2026 | C91: Instagram | D91: SABRINA CARPENTER | E91: CARRUSEL | F91: maicao | G91: teaser lemon pie - josevalenh | K91: 31024 | L91: 11297 | M91: 568 | N91: 67 | O91: 7 | P91: 6 | Q91: 5 | R91: 0 | S91: 0 | T91: 653 | U91: 5.7802957 | W91: 0 | Y91: Sí | Z91: Sí | AA91: No | AB91: No
A92: Marzo 2026 | C92: Instagram | D92: SABRINA CARPENTER | E92: CARRUSEL | F92: maicao | G92: teaser lemon pie - cata_fdez94 | K92: 51476 | L92: 16889 | M92: 1051 | N92: 83 | O92: 6 | P92: 10 | Q92: 10 | R92: 0 | S92: 0 | T92: 1160 | U92: 6.8683759 | W92: 0 | Y92: Sí | Z92: Sí | AA92: No | AB92: No
A93: Marzo 2026 | C93: Instagram | D93: PANTENE | E93: REEL | F93: maicao | G93: pantene molecular - victoriahelo | K93: 21557 | L93: 13755 | M93: 175 | N93: 27 | O93: 44 | P93: 12 | Q93: 7 | R93: 0 | S93: 0 | T93: 265 | U93: 1.9265722 | W93: 0 | Y93: Sí | Z93: Sí | AA93: No | AB93: No
... A118: Marzo 2026 | C118: TikTok | D118: EGC | E118: VIDEO | F118: maicao | G118: Labiales petrizzio | K118: 5688 | L118: 5500 | M118: 94 | N118: 9 | O118: 9 | P118: 0 | Q118: 9 | R118: 0 | S118: 0 | T118: 121 | U118: 2.2 | W118: 0 | Y118: Sí | Z118: Sí | AA118: No | AB118: No
A119: Marzo 2026 | C119: Facebook | D119: CAMPAÑA | E119: POST | F119: maicao | G119: productos a 1000 | J119: Alcance | K119: 836900 | L119: 438800 | M119: 466 | N119: 6 | O119: 0 | P119: 0 | Q119: 7 | R119: 0 | S119: 30 | T119: 509 | U119: 0.11599818 | V119: sí | W119: 200000 | Y119: Sí | Z119: Sí | AA119: No | AB119: No
A120: Marzo 2026 | C120: Facebook | D120: CAMPAÑA | E120: CARRUSEL | F120: maicao | G120: lanzamientos de marzo | J120: Alcance | K120: 708300 | L120: 392100 | M120: 246 | N120: 2 | O120: 0 | P120: 0 | Q120: 5 | R120: 0 | S120: 21 | T120: 274 | U120: 0.069880133 | V120: sí | W120: 200000 | Y120: Sí | Z120: Sí | AA120: No | AB120: No
A121: Marzo 2026 | C121: Facebook | D121: EGC | E121: CARRUSEL | F121: maicao | G121: repost productos desde 1000 | K121: 28500 | L121: 19300 | M121: 76 | N121: 3 | O121: 0 | P121: 0 | Q121: 0 | R121: 0 | S121: 0 | T121: 79 | U121: 0.40932642 | W121: 0 | Y121: Sí | Z121: Sí | AA121: No | AB121: No
A122: Marzo 2026 | C122: Facebook | D122: EXTRA | E122: VIDEO | F122: maicao | G122: recap 2025 | K122: 2800 | L122: 2400 | M122: 12 | N122: 0 | O122: 0 | P122: 0 | Q122: 0 | R122: 0 | S122: 0 | T122: 12 | U122: 0.5 | W122: 0 | Y122: Sí | Z122: Sí | AA122: No | AB122: No
A123: Marzo 2026 | C123: Facebook | D123: EXTRA | E123: VIDEO | F123: maicao | G123: recap bienvenida squad y consejeras | K123: 3121 | L123: 2781 | M123: 12 | N123: 0 | O123: 0 | P123: 0 | Q123: 0 | R123: 0 | S123: 0 | T123: 12 | U123: 0.43149946 | W123: 0 | Y123: Sí | Z123: Sí | AA123: No | AB123: No
A124: Marzo 2026 | C124: Facebook | D124: UGC | E124: VIDEO | F124: maicao | G124: repost hábitos para mejorar tu piel | K124: 7200 | L124: 4900 | M124: 17 | N124: 0 | O124: 0 | P124: 0 | Q124: 1 | R124: 0 | S124: 0 | T124: 18 | U124: 0.36734694 | W124: 0 | Y124: Sí | Z124: Sí | AA124: No | AB124: No
A125: Marzo 2026 | C125: Facebook | D125: UGC | E125: VIDEO | F125: maicao | G125: repost ugc bubble maybelline | J125: alcance | K125: 531300 | L125: 325000 | M125: 479 | N125: 8 | O125: 0 | P125: 0 | Q125: 118 | R125: 0 | S125: 120 | T125: 725 | U125: 0.22307692 | V125: sí | W125: 200000 | Y125: Sí | Z125: Sí | AA125: No | AB125: No
...

Sheet 02_Audience
A1: 02_Audience
A2: Seguidores y demografía por plataforma. Alimenta slides de audiencia.
A4: Mes | B4: Plataforma | C4: Seguidores | D4: Seguidores mes anterior | E4: Crecimiento | F4: Mujeres % | G4: Hombres % | H4: 18-24 % | I4: 25-34 % | J4: 35-44 % | K4: 45-54 % | L4: 55+ % | M4: Ciudad 1 | N4: Ciudad 2 | O4: Notas
A5: Marzo 2026 | B5: Instagram | C5: 332382 | D5: 330993 | E5: =C5-D5 | F5: 92.3 | G5: 7.7 | H5: 4 | I5: 28 | J5: 35 | K5: 17 | M5: Santiago | N5: Concepción | O5: Datos de reporte marzo
A6: Marzo 2026 | B6: Facebook | C6: 565501 | D6: 565071 | E6: =C6-D6 | F6: 97.2 | G6: 2.8 | H6: 2 | I6: 27 | J6: 30 | K6: 21 | M6: Santiago | N6: Viña del Mar | O6: Datos de reporte marzo
A7: Marzo 2026 | B7: TikTok | C7: 30120 | D7: 27352 | E7: =C7-D7 | F7: 84 | G7: 16 | H7: 36 | I7: 32 | J7: 13 | K7: 8 | L7: 10 | M7: Santiago | N7: Otros | O7: Datos de reporte marzo

Sheet 03_Paid_Media
A1: 03_Paid_Media
A2: Inversión separada de contenidos para evitar descuadres entre pauta, Squad y plataformas.
A4: Mes | B4: Plataforma | C4: Segmento | D4: Monto | E4: Fuente | F4: Objetivo | G4: Comentario | H4: Incluir Overview | I4: Incluir Plataforma | J4: Validación
A5: Marzo 2026 | B5: Instagram | C5: Plataforma | D5: 850000 | E5: Reporte/PDF | F5: Visibilidad | G5: Valor a confirmar contra pauta final | H5: Sí | I5: Sí | J5: Revisar
A6: Marzo 2026 | B6: Facebook | C6: Plataforma | D6: 1000000 | E6: Reporte/PDF | F6: Visibilidad | G6: Valor reportado en slide Facebook | H6: Sí | I6: Sí | J6: Revisar
A7: Marzo 2026 | B7: TikTok | C7: Plataforma | D7: 1400000 | E7: Reporte/PDF | F7: Visibilidad | G7: Valor reportado en slide TikTok | H7: Sí | I7: Sí | J7: OK
A8: Marzo 2026 | B8: Squad | C8: Influencers | D8: 400000 | E8: Reporte/PDF | F8: Alcance + engagement | G8: Valor reportado en slide Squad | H8: Sí | I8: No | J8: OK
A9: Marzo 2026 | B9: Ajuste / Sin asignar | C9: Control | D9: 150400 | E9: Diferencia | F9: Cuadre total | G9: Diferencia para llegar a $3.800.400; validar origen exacto | H9: Sí | I9: No | J9: Revisar

Sheet 04_Squad
A1: 04_Squad
A2: Desempeño de creadoras / perfiles. Una fila por talento.
A4: Mes | B4: Talento | C4: Formatos | D4: Views | E4: Alcance | F4: Interacciones | G4: ER % | H4: Monto | I4: Insight | J4: Recomendación | K4: Incluir PPT | L4: Prioridad | M4: Notas
A5: Marzo 2026 | B5: Skarleth Labra | C5: 1 Reel + 1 Story + 1 TikTok | D5: 2052186 | E5: 997455 | F5: 44792 | G5: 4.5 | H5: 200000 | I5: Alto ER pese a menor volumen vs febrero; mantiene calidad de interacción. | J5: Mantener GRWM/carruseles con integración natural de producto. | K5: Sí | L5: Alta
A6: Marzo 2026 | B6: Busquilla | C6: 1 TikTok + 1 Reel + 1 Stories | D6: 87875 | E6: 61011 | F6: 691 | G6: 1.1 | H6: 0 | I6: Contenido orientado a ofertas generó clicks, pero menor escala por pauta/contenidos. | J6: Reforzar stories con navegación web orgánica. | K6: Sí | L6: Media
A7: Marzo 2026 | B7: Camila Andrade | C7: 1 Reel + 3 Stories | D7: 811352 | E7: 475505 | F7: 3917 | G7: 0.8 | H7: 200000 | I7: Desempeño eficiente; TikTok más acotado por integración menos natural del texto/producto. | J7: Optimizar integración nativa de productos en video. | K7: Sí | L7: Media
A8: Marzo 2026 | B8: Disley Ramos | C8: 1 Reel + 1 TikTok + Story | D8: 1685662 | E8: 486855 | F8: 10746 | G8: 2.2 | H8: 0 | I8: Nuevo rostro aporta volumen y cercanía desde humor/contenido íntimo. | J8: Mantener perfiles culturales con lenguaje propio. | K8: Sí | L8: Alta

Sheet 05_MMPP
A1: 05_MMPP
A2: Segmento marcas propias/campañas especiales. Consolidado para slide propia.
A4: Mes | B4: Campaña/Segmento | C4: Contenidos | D4: Views | E4: Alcance | F4: Interacciones | G4: ER % | H4: Marcas | I4: Comentario general | J4: Usar en PPT
A5: Marzo 2026 | B5: MMPP / SAMY + marcas asociadas | C5: 14 | D5: 3336786 | E5: 1443025 | F5: 13463 | G5: 1 | H5: SAMY, The Pure Solutions, face facts Wave, Beauty 100 | I5: Buen recibimiento cualitativo; comentarios positivos sobre productos, calidad y precios. | J5: Sí

Sheet 06_Competencia
A1: 06_Competencia
A2: Benchmark en formato largo. Una fila por marca + plataforma + mes.
A4: Mes | B4: Plataforma | C4: Marca | D4: Seguidores | E4: Interacciones | F4: Fuente | G4: Observación | H4: Usar en gráfico | I4: Prioridad | J4: Notas
A5: Marzo 2026 | B5: Instagram | C5: Maicao | F5: Carga manual / social listening | G5: Posición intermedia; DBS domina estética/plataforma según reporte. | H5: Sí | I5: Media | J5: Pendiente cargar valores exactos desde benchmark
A6: Marzo 2026 | B6: Instagram | C6: Preunic | F6: Carga manual / social listening | H6: Sí | I6: Media | J6: Pendiente cargar valores exactos desde benchmark
A7: Marzo 2026 | B7: Instagram | C7: Dr. Simi | F7: Carga manual / social listening | H7: Sí | I7: Media | J7: Pendiente cargar valores exactos desde benchmark
A8: Marzo 2026 | B8: Instagram | C8: DBS | F8: Carga manual / social listening | H8: Sí | I8: Media | J8: Pendiente cargar valores exactos desde benchmark
A9: Marzo 2026 | B9: Instagram | C9: Blush-Bar | F9: Carga manual / social listening | H9: Sí | I9: Media | J9: Pendiente cargar valores exactos desde benchmark
A10: Marzo 2026 | B10: Instagram | C10: Beauty Plus | F10: Carga manual / social listening | H10: Sí | I10: Media | J10: Pendiente cargar valores exactos desde benchmark
A11: Marzo 2026 | B11: Facebook | C11: Maicao | F11: Carga manual / social listening | G11: Maicao lidera en Facebook según reporte. | H11: Sí | I11: Media | J11: Pendiente cargar valores exactos desde benchmark
A12: Marzo 2026 | B12: Facebook | C12: Preunic | F12: Carga manual / social listening | H12: Sí | I12: Media | J12: Pendiente cargar valores exactos desde benchmark
A13: Marzo 2026 | B13: Facebook | C13: Dr. Simi | F13: Carga manual / social listening | H13: Sí | I13: Media | J13: Pendiente cargar valores exactos desde benchmark
A14: Marzo 2026 | B14: Facebook | C14: DBS | F14: Carga manual / social listening | H14: Sí | I14: Media | J14: Pendiente cargar valores exactos desde benchmark
A15: Marzo 2026 | B15: Facebook | C15: Blush-Bar | F15: Carga manual / social listening | H15: Sí | I15: Media | J15: Pendiente cargar valores exactos desde benchmark
A16: Marzo 2026 | B16: Facebook | C16: Beauty Plus | F16: Carga manual / social listening | H16: Sí | I16: Media | J16: Pendiente cargar valores exactos desde benchmark
A17: Marzo 2026 | B17: TikTok | C17: Maicao | F17: Carga manual / social listening | G17: Mayor espacio de expansión y posicionamiento. | H17: Sí | I17: Media | J17: Pendiente cargar valores exactos desde benchmark
A18: Marzo 2026 | B18: TikTok | C18: Preunic | F18: Carga manual / social listening | H18: Sí | I18: Media | J18: Pendiente cargar valores exactos desde benchmark
A19: Marzo 2026 | B19: TikTok | C19: Dr. Simi | F19: Carga manual / social listening | H19: Sí | I19: Media | J19: Pendiente cargar valores exactos desde benchmark
A20: Marzo 2026 | B20: TikTok | C20: DBS | F20: Carga manual / social listening | H20: Sí | I20: Media | J20: Pendiente cargar valores exactos desde benchmark
A21: Marzo 2026 | B21: TikTok | C21: Blush-Bar | F21: Carga manual / social listening | H21: Sí | I21: Media | J21: Pendiente cargar valores exactos desde benchmark
A22: Marzo 2026 | B22: TikTok | C22: Beauty Plus | F22: Carga manual / social listening | H22: Sí | I22: Media | J22: Pendiente cargar valores exactos desde benchmark

Sheet 07_Insights
A1: 07_Insights
A2: Narrativa cualitativa estructurada: hallazgo + evidencia + implicancia + recomendación.
A4: Mes | B4: Sección | C4: Tipo | D4: Hallazgo | E4: Evidencia | F4: Implicancia | G4: Recomendación | H4: Prioridad | I4: Usar en PPT | J4: Slide sugerida | K4: Estado
A5: Marzo 2026 | B5: Overview | C5: Performance | D5: La visibilidad creció, pero el engagement se diluyó. | E5: Views +24.5% vs febrero; ER cae de 2.9% a 1.3%. | F5: La inversión y el mix ampliaron audiencia, pero con menor profundidad de interacción. | G5: Optimizar hooks de 3 segundos y CTAs para retener e incentivar acción. | H5: Alta | I5: Sí | J5: Resumen ejecutivo | K5: Aprobado
A6: Marzo 2026 | B6: TikTok | C6: Canal | D6: TikTok se consolida como principal motor de visibilidad. | E6: 4.5M views, 17.148 interacciones y ER cercano a 1%. | F6: El lenguaje nativo y educativo conecta mejor que lo explícitamente publicitario. | G6: Potenciar formatos conversacionales, EGC y tutoriales útiles. | H6: Alta | I6: Sí | J6: TikTok | K6: Aprobado
A7: Marzo 2026 | B7: Facebook | C7: Canal | D7: Facebook repunta y mantiene comunidad sólida. | E7: 565.501 seguidores y +430 vs mes anterior. | F7: Es útil para formatos gráficos/oferta y audiencias más maduras. | G7: Mantener comunicación táctica, ofertas y piezas simples de alto entendimiento. | H7: Media | I7: Sí | J7: Facebook | K7: Aprobado
A8: Marzo 2026 | B8: Instagram | C8: Canal | D8: Instagram mantiene base fuerte, pero con interacción más moderada. | E8: 332.382 seguidores y +1.389 vs febrero; ER 1.4%. | F8: La salida del contexto festivalero reduce conversación espontánea. | G8: Reforzar cultura pop, UGC educativo y colaboraciones con creadoras. | H8: Alta | I8: Sí | J8: Instagram | K8: Aprobado
A9: Marzo 2026 | B9: Squad | C9: Talentos | D9: Nuevos rostros ayudaron a amortiguar la baja vs febrero. | E9: Disley aporta 1.68M views sin pauta directa. | F9: Talentos con lenguaje propio pueden sostener relevancia cultural. | G9: Sumar perfiles de nicho y tendencia de forma ocasional. | H9: Alta | I9: Sí | J9: Squad | K9: Aprobado
A10: Marzo 2026 | B10: Competencia | C10: Benchmark | D10: Maicao lidera en Facebook, pero tiene oportunidad en TikTok. | E10: Reporte competitivo: posición fuerte en FB, intermedia en IG y menor en TikTok. | F10: La oportunidad no es solo volumen; es posicionamiento orgánico y diferencial. | G10: Desarrollar una estrategia TikTok consistente con EGC, UGC y hooks nativos. | H10: Alta | I10: Sí | J10: Competencia | K10: Aprobado

Sheet 08_Recomendaciones
A1: 08_Recomendaciones
A2: Backlog accionable que puede alimentar una slide de próximos pasos.
A4: Mes | B4: Prioridad | C4: Área | D4: Recomendación | E4: Racional | F4: Impacto esperado | G4: Esfuerzo | H4: Responsable | I4: Status | J4: Usar en PPT
A5: Marzo 2026 | B5: Alta | C5: Creatividad | D5: Implementar hooks de 3 segundos en Reels/TikTok. | E5: El ER cayó al ampliar audiencias; necesitamos retener antes de explicar. | F5: Mayor retención e interacción | G5: Medio | H5: Agencia | I5: Propuesto | J5: Sí
A6: Marzo 2026 | B6: Alta | C6: Contenido | D6: Priorizar tutoriales, hacks y contenidos guardables. | E6: Los contenidos educativos generan guardados e interés práctico. | F6: Más guardados y engagement de calidad | G6: Medio | H6: Agencia | I6: Propuesto | J6: Sí
A7: Marzo 2026 | B7: Media | C7: Influencers | D7: Sumar talentos por nicho: skincare, maquillaje pro, Gen Z. | E7: Competencia gana por estética/comunidad; nichos pueden diferenciar. | F7: Mayor relevancia cultural | G7: Alto | H7: Cliente/Agencia | I7: Propuesto | J7: Sí
A8: Marzo 2026 | B8: Media | C8: Reporting | D8: Separar pauta real de pauta por contenido en tabla dedicada. | E8: La inversión total no cuadra con suma directa de columna monto. | F8: Menos descuadres y auditoría más clara | G8: Bajo | H8: Data | I8: En proceso | J8: Sí

Sheet 09_Validaciones
A1: 09_Validaciones
A2: Control de calidad mensual: descuadres, flags y criterios de inclusión.
A4: Bloque | B4: Métrica | C4: Calculado modelo | D4: Valor esperado / control | E4: Diferencia | F4: Estado | G4: Acción sugerida | H4: Severidad | I4: Responsable | J4: Notas
A5: Overview | B5: Views | C5: =SUMIFS('01_Content_Raw'!K:K,'01_Content_Raw'!A:A,'00_Control'!B6,'01_Content_Raw'!Y:Y,"Sí") | D5: 16486179 | E5: =C5-D5 | F5: =IF(E5=0,"OK","Revisar") | G5: Validar diferencia de 270 views vs PPT/PDF | H5: Baja | I5: Data | J5: Probable ajuste manual o redondeo
A6: Overview | B6: Alcance | C6: =SUMIFS('01_Content_Raw'!L:L,'01_Content_Raw'!A:A,'00_Control'!B6,'01_Content_Raw'!Y:Y,"Sí") | D6: 8211420 | E6: =C6-D6 | F6: =IF(E6=0,"OK","Revisar") | G6: OK si cuadra con reporte | H6: Alta | I6: Data
A7: Overview | B7: Interacciones | C7: =SUMIFS('01_Content_Raw'!T:T,'01_Content_Raw'!A:A,'00_Control'!B6,'01_Content_Raw'!Y:Y,"Sí") | D7: 110695 | E7: =C7-D7 | F7: =IF(E7=0,"OK","Revisar") | G7: OK si cuadra con reporte | H7: Alta | I7: Data
A8: Overview | B8: Contenidos | C8: =COUNTIFS('01_Content_Raw'!A:A,'00_Control'!B6,'01_Content_Raw'!Y:Y,"Sí") | D8: 156 | E8: =C8-D8 | F8: =IF(E8=0,"OK","Revisar criterio") | G8: Definir exclusiones Squad/MMPP | H8: Media | I8: Data | J8: Excel tiene 158 filas de contenido
A9: Paid Media | B9: Inversión | C9: =SUMIFS('03_Paid_Media'!D:D,'03_Paid_Media'!A:A,'00_Control'!B6,'03_Paid_Media'!H:H,"Sí") | D9: 3800400 | E9: =C9-D9 | F9: =IF(E9=0,"OK","Revisar") | G9: Validar fuente de ajuste / sin asignar | H9: Alta | I9: Data/Media
A10: Data hygiene | B10: Filas sin plataforma | C10: =COUNTIFS('01_Content_Raw'!A:A,'00_Control'!B6,'01_Content_Raw'!C:C,"") | D10: 0 | E10: =C10-D10 | F10: =IF(C10=0,"OK","Revisar") | G10: Completar plataforma | H10: Alta | I10: Agencia
A11: Data hygiene | B11: Filas sin categoría | C11: =COUNTIFS('01_Content_Raw'!A:A,'00_Control'!B6,'01_Content_Raw'!D:D,"") | D11: 0 | E11: =C11-D11 | F11: =IF(C11=0,"OK","Revisar") | G11: Completar categoría | H11: Media | I11: Agencia
A12: Narrativa | B12: Insights aprobados | C12: =COUNTIFS('07_Insights'!I:I,"Sí",'07_Insights'!K:K,"Aprobado") | D12: 6 | E12: =C12-D12 | F12: =IF(C12>=D12,"OK","Revisar") | G12: Aprobar insights antes de generar PPT | H12: Media | I12: Strategy

Sheet 10_PPT_Mapping
A1: 10_PPT_Mapping
A2: Mapa técnico: define qué celda/tabla alimenta cada slide y cada placeholder de la PPT.
A4: Slide | B4: Nombre slide | C4: Elemento PPT / Placeholder | D4: Tipo | E4: Fuente Excel | F4: Regla / Filtro | G4: Formato | H4: Estado | I4: Notas | J4: Prioridad
A5: 1 | B5: Portada | C5: {{mes_reporte}} | D5: Texto | E5: 00_Control!B6 | F5: Mes actual | G5: Texto | H5: Pendiente | I5: Se usará en plantilla PPT | J5: Alta
A6: 2 | B6: Executive overview | C6: {{overview_views}} | D6: KPI | E6: 09_Validaciones!C5 | F6: Views incluidos overview | G6: #,##0 | H6: Pendiente | J6: Alta
A7: 2 | B7: Executive overview | C7: {{overview_reach}} | D7: KPI | E7: 09_Validaciones!C6 | F7: Alcance incluido overview | G7: #,##0 | H7: Pendiente | J7: Alta
A8: 2 | B8: Executive overview | C8: {{overview_interactions}} | D8: KPI | E8: 09_Validaciones!C7 | F8: Interacciones incluidas overview | G8: #,##0 | H8: Pendiente | J8: Alta
A9: 2 | B9: Executive overview | C9: {{overview_investment}} | D9: KPI | E9: 09_Validaciones!C9 | F9: Inversión incluida overview | G9: $#,##0 | H9: Pendiente | J9: Alta
A10: 3 | B10: Plataformas | C10: chart_platform_views | D10: Gráfico | E10: 01_Content_Raw | F10: SUMIFS por plataforma | G10: Bar chart | H10: Pendiente | I10: Gráfico editable PPT | J10: Alta
A11: 4 | B11: Instagram | C11: {{ig_insight}} | D11: Texto | E11: 07_Insights | F11: Sección=Instagram, Usar=Sí | G11: Texto | H11: Pendiente | J11: Alta
A12: 5 | B12: Facebook | C12: {{fb_insight}} | D12: Texto | E12: 07_Insights | F12: Sección=Facebook, Usar=Sí | G12: Texto | H12: Pendiente | J12: Media
A13: 6 | B13: TikTok | C13: {{tiktok_insight}} | D13: Texto | E13: 07_Insights | F13: Sección=TikTok, Usar=Sí | G13: Texto | H13: Pendiente | J13: Alta
A14: 7 | B14: Squad | C14: chart_squad_performance | D14: Gráfico | E14: 04_Squad | F14: Usar en PPT=Sí | G14: Bubble/bar | H14: Pendiente | J14: Alta
A15: 8 | B15: MMPP | C15: {{mmpp_comment}} | D15: Texto | E15: 05_MMPP | F15: Usar en PPT=Sí | G15: Texto | H15: Pendiente | J15: Media
A16: 9 | B16: Competencia | C16: chart_competencia | D16: Gráfico | E16: 06_Competencia | F16: Usar gráfico=Sí | G16: Clustered bar | H16: Pendiente | I16: Requiere carga exacta | J16: Alta
A17: 10 | B17: Recomendaciones | C17: recommendation_cards | D17: Texto/tabla | E17: 08_Recomendaciones | F17: Usar PPT=Sí | G17: Cards | H17: Pendiente | J17: Alta

Sheet 11_Diccionario
A1: 11_Diccionario
A2: Definiciones para estandarizar la carga mensual y evitar ambigüedades.
A4: Campo | B4: Definición | C4: Tipo | D4: Obligatorio | E4: Valores permitidos / Ejemplo | F4: Notas
A5: Mes | B5: Mes del reporte en formato 'Marzo 2026'. | C5: Texto | D5: Sí | E5: Marzo 2026 | F5: Debe coincidir con 00_Control
A6: Plataforma | B6: Red social donde se publicó el contenido. | C6: Categoría | D6: Sí | E6: Instagram / Facebook / TikTok | F6: Usar nombres normalizados
A7: Categoría | B7: Tipo estratégico del contenido. | C7: Categoría | D7: Sí | E7: UGC / EGC / CAMPAÑA / EXTRA / SQUAD / CONCURSO | F7: Permite agrupar
A8: Formato | B8: Formato de publicación. | C8: Categoría | D8: Sí | E8: Story / Reel / Carrusel / Post / TikTok
A9: Talento | B9: Cuenta o persona protagonista. | C9: Texto | D9: No | E9: maicao / Disley Ramos / Skarleth Labra | F9: Clave para Squad
A10: Interacciones totales | B10: Suma de likes, comentarios, clicks, stickers, guardados, repost y compartidos. | C10: Número | D10: Sí | E10: 110695 | F10: Depende de métrica disponible por plataforma
A11: ER % | B11: Engagement rate en puntos porcentuales, no decimal. | C11: Número | D11: Sí | E11: 1.3 | F11: 1.3 significa 1.3%
A12: Incluir Overview | B12: Controla si la pieza suma en la slide overview. | C12: Sí/No | D12: Sí | E12: Sí / No | F12: Evita descuadres
A13: Incluir Plataforma | B13: Controla si suma dentro de la slide de plataforma. | C13: Sí/No | D13: Sí | E13: Sí / No | F13: Por ejemplo excluir Squad si se reporta separado
A14: Insight | B14: Texto cualitativo estructurado para la PPT. | C14: Texto | D14: No | E14: Hallazgo + evidencia + implicancia | F14: Debe ser aprobado antes del PPT

Sheet 12_Chart_Data
A1: 12_Chart_Data
A2: Tablas auxiliares para gráficos automáticos. Puede ocultarse en producción.
A4: Plataforma | B4: Views | C4: Alcance | D4: Interacciones | E4: Contenidos
A5: Instagram | B5: 8231124 | C5: 3962613 | D5: 58723 | E5: 99
A6: Facebook | B6: 3223306 | C6: 1905477 | D6: 4656 | E6: 31
A7: TikTok | B7: 5031479 | C7: 2343330 | D7: 47316 | E7: 28

Sheet 13_Platform_KPIs
A1: KPIs oficiales por plataforma
A2: Editar esta hoja para que cambien los KPIs de Instagram, Facebook, TikTok y la slide de portafolio de canales
A4: Mes | B4: Plataforma | C4: Views | D4: Views mes anterior | E4: Alcance | F4: Alcance mes anterior | G4: Interacciones | H4: Interacciones mes anterior | I4: ER % | J4: ER % mes anterior | K4: Contenidos | L4: Contenidos mes anterior | M4: Stories | N4: Reels | O4: Carruseles | P4: Post | Q4: Presupuesto | R4: Presupuesto mes anterior | S4: Top 1 nombre | T4: Top 1 valor | U4: Top 2 nombre | V4: Top 2 valor | W4: Top 3 nombre | X4: Top 3 valor | Y4: Insight corto | Z4: Oportunidad / Nota
A5: Marzo 2026 | B5: Instagram | C5: 8231124 | D5: 6416616 | E5: 3962613 | F5: 3972683 | G5: 58723 | H5: 126125 | I5: 1.4 | J5: 3.2 | K5: 92 | L5: 82 | M5: 68 | N5: 13 | O5: 10 | P5: 0 | Q5: 1670000 | R5: 850000 | S5: Bubble Maybelline | T5: 1,51M | U5: Check Bienvenida | V5: 763K | W5: Make up SAMY | X5: 1,69M | Y5: Visibilidad alta con engagement moderado | Z5: Pasar de piezas aisladas a series guardables.
A6: Marzo 2026 | B6: Facebook | C6: 3223306 | D6: 1905477 | E6: 1905477 | F6: 1119912 | G6: 4656 | H6: 3678 | I6: 0.2 | J6: 0.3 | K6: 31 | L6: 28 | M6: 19 | N6: 9 | O6: 2 | P6: 1 | Q6: 1000000 | R6: 1000000 | S6: Prod. $1.000 | T6: 526K | U6: Máscara Bubble | V6: 508K | W6: SAMY | X6: 531K | Y6: Liderazgo comunitario y buena respuesta a ofertas | Z6: Nota: stories incompletas por error de plataforma antes del 20 de marzo.
A7: Marzo 2026 | B7: TikTok | C7: 4522490 | D7: 3910125 | E7: 1904830 | F7: 2200681 | G7: 17148 | H7: 15914 | I7: 0.9 | J7: 0.7 | K7: 25 | L7: 34 | M7: 0 | N7: 0 | O7: 0 | P7: 0 | Q7: 1400000 | R7: 780000 | S7: Maquillaje principiantes | T7: 2.880 | U7: EGC Garnier | V7: 630 | W7: UGC hábitos piel | X7: 1.387 | Y7: Motor de visibilidad y autenticidad | Z7: Potenciar CTA a comentar, guardar y seguir.

Sheet 14_Mapa_Slide_por_Slide
A1: Mapa slide por slide
A2: Qué editar en Excel para que cambie cada parte de la presentación
A4: Slide | B4: Nombre / objetivo | C4: Qué cambia en PPT | D4: Hoja que debes editar | E4: Campos principales | F4: Automatizado v03 | G4: Notas
A5: 1 | B5: Portada | C5: Cliente, mes, meta de portada, KPIs grandes | D5: 00_Control / 09_Validaciones | E5: Cliente, Mes actual, Views, Alcance, Interacciones | F5: Sí | G5: Los KPIs grandes vienen de Overview.
A6: 2 | B6: Dashboard ejecutivo | C6: KPIs totales, variaciones, inversión, lectura de negocio base | D6: 09_Validaciones / 03_Paid_Media / 00_Control | E6: Views, Alcance, ER, Interacciones, Inversión, Mes anterior | F6: Sí parcial | G6: La narrativa sigue editable vía 07_Insights en la próxima fase.
A7: 3 | B7: Qué cambió | C7: ER, inversión, contenidos y decisión recomendada | D7: 09_Validaciones / 03_Paid_Media / 07_Insights | E7: ER actual, inversión actual, contenidos, hallazgo | F7: Sí parcial | G7: Los números cambian; textos largos aún se revisan manualmente.
A8: 4 | B8: Portafolio de canales | C8: Views, alcance, ER y seguidores por plataforma | D8: 13_Platform_KPIs / 02_Audience | E8: Views, Alcance, ER %, Interacciones, Seguidores | F8: Sí | G8: Cambio clave v03: sale de Excel, no de config/defaults.json.
A9: 5 | B9: Instagram | C9: KPIs, seguidores, contenidos, presupuesto, formatos, top 3 | D9: 13_Platform_KPIs / 02_Audience | E9: Instagram: Views, Alcance, Interacciones, ER, Stories, Reels, Carruseles, Top 1-3 | F9: Sí | G9: Editar fila Instagram en 13_Platform_KPIs.
A10: 6 | B10: Facebook | C10: KPIs, seguidores, formatos, top 3, nota de data | D10: 13_Platform_KPIs / 02_Audience | E10: Facebook: Views, Alcance, ER, Stories, Reels, Carruseles, Post, Top 1-3 | F10: Sí | G10: Editar fila Facebook en 13_Platform_KPIs.
A11: 7 | B11: TikTok | C11: KPIs, seguidores, edad, top 3 y oportunidad | D11: 13_Platform_KPIs / 02_Audience | E11: TikTok: Views, Interacciones, ER, edad, Top 1-3 | F11: Sí | G11: Editar fila TikTok en 13_Platform_KPIs y audiencia en 02_Audience.
A12: 8 | B12: TikTok mix creativo | C12: UGC, EGC, extras/campañas por objetivo | D12: 01_Content_Raw / 07_Insights | E12: Categoría, Views, Interacciones, ER, insight | F12: Pendiente | G12: Esta es la próxima conexión recomendada.
A13: 9 | B13: Squad | C13: Totales y performance por integrante | D13: 04_Squad | E13: Talento, Views, Alcance, Interacciones, ER %, Monto | F13: Sí | G13: Editar una fila por talento.
A14: 10 | B14: MMPP | C14: KPIs, mix, comentario cualitativo | D14: 05_MMPP | E14: Contenidos, Views, Alcance, Interacciones, ER, Comentario general | F14: Sí | G14: Editar primera fila o agregar más segmentos.
A15: 11 | B15: Competencia | C15: Lecturas competitivas y señales por marca | D15: 06_Competencia / 07_Insights | E15: Marca, Plataforma, Seguidores, Interacciones, Observación | F15: Pendiente | G15: Data estructurada lista; visual aún estática.
A16: 12 | B16: Plan 30 días | C16: Prioridades y recomendaciones | D16: 08_Recomendaciones | E16: Prioridad, Área, Recomendación, Impacto esperado | F16: Pendiente | G16: Próxima fase: tomar top 4 recomendaciones.
A18: Nota v04 | B18: El generador imprime alertas si falta data por mes/plataforma. Si falta dato en PPT se muestra "Dato pendiente".

Sheet 15_Checklist_Generacion
A1: 15_Checklist_Generacion
A2: Checklist de control antes de generar la PPT. Las fórmulas dependen de 00_Control y hojas fuente.
A4: Check | B4: Resultado esperado | C4: Estado | D4: Cómo corregir
A5: Mes actual como texto | B5: 00_Control!B6 debe verse como Marzo 2026 | C5: =IF(ISNUMBER(00_Control!B6),"REVISAR","OK") | D5: Selecciona celda, formato Texto, escribe 'Marzo 2026
A6: Fila Instagram en KPIs | B6: Debe existir mes + plataforma en 13_Platform_KPIs | C6: =IF(COUNTIFS('13_Platform_KPIs'!$A:$A,00_Control!$B$6,'13_Platform_KPIs'!$B:$B,"Instagram")=1,"OK","REVISAR") | D6: Duplicar fila del mes anterior y cambiar mes/plataforma.
A7: Fila Facebook en KPIs | B7: Debe existir mes + plataforma en 13_Platform_KPIs | C7: =IF(COUNTIFS('13_Platform_KPIs'!$A:$A,00_Control!$B$6,'13_Platform_KPIs'!$B:$B,"Facebook")=1,"OK","REVISAR") | D7: Duplicar fila del mes anterior y cambiar mes/plataforma.
A8: Fila TikTok en KPIs | B8: Debe existir mes + plataforma en 13_Platform_KPIs | C8: =IF(COUNTIFS('13_Platform_KPIs'!$A:$A,00_Control!$B$6,'13_Platform_KPIs'!$B:$B,"TikTok")=1,"OK","REVISAR") | D8: Duplicar fila del mes anterior y cambiar mes/plataforma.
A9: Audiencia Instagram | B9: Debe existir mes + plataforma en 02_Audience | C9: =IF(COUNTIFS('02_Audience'!$A:$A,00_Control!$B$6,'02_Audience'!$B:$B,"Instagram")=1,"OK","REVISAR") | D9: Completar seguidores y demografía.
A10: Audiencia Facebook | B10: Debe existir mes + plataforma en 02_Audience | C10: =IF(COUNTIFS('02_Audience'!$A:$A,00_Control!$B$6,'02_Audience'!$B:$B,"Facebook")=1,"OK","REVISAR") | D10: Completar seguidores y demografía.
A11: Audiencia TikTok | B11: Debe existir mes + plataforma en 02_Audience | C11: =IF(COUNTIFS('02_Audience'!$A:$A,00_Control!$B$6,'02_Audience'!$B:$B,"TikTok")=1,"OK","REVISAR") | D11: Completar seguidores y demografía.
A12: MMPP activo | B12: Si la slide aplica, debe existir una fila activa | C12: =IF(COUNTIFS('05_MMPP'!$A:$A,00_Control!$B$6,'05_MMPP'!$J:$J,"Sí")>=1,"OK","REVISAR") | D12: Completar 05_MMPP o marcar Usar en PPT = Sí.
A13: Pauta overview | B13: Debe haber inversión marcada para overview | C13: =IF(SUMIFS('03_Paid_Media'!$D:$D,'03_Paid_Media'!$A:$A,00_Control!$B$6,'03_Paid_Media'!$H:$H,"Sí")>0,"OK","REVISAR") | D13: Completar 03_Paid_Media e Incluir Overview = Sí.
A16: Estado general | B16: =IF(COUNTIF(C5:C13,"REVISAR")>0,"REVISAR","OK") | C16: Antes de generar, corregir checks en REVISAR.
